[29/Feb/2024 19:10:54] "GET /cart-list/ HTTP/1.1" 200 11950
[29/Feb/2024 19:10:56] "GET /cart/count/ HTTP/1.1" 200 21
[29/Feb/2024 19:10:56] "GET /checkout/ HTTP/1.1" 200 28079
[29/Feb/2024 19:10:57] "GET /cart/count/ HTTP/1.1" 200 21
[29/Feb/2024 19:11:00] "GET /api/stock-check/ HTTP/1.1" 200 49
[29/Feb/2024 19:15:20] "GET /api/stock-check/ HTTP/1.1" 200 49
Error: {"status":false,"message":"Transaction not found","meta":{"nextStep":"Ensure that you're passing the reference of a transaction that exists on this integration"},"type":"validation_error","code":"transaction_not_found"}
Internal Server Error: /api/order-confirm/
Traceback (most recent call last):
  File "/home/ubuntu/venv/lib/python3.10/site-packages/django/db/backends/utils.py", line 89, in _execute
    return self.cursor.execute(sql, params)
  File "/home/ubuntu/venv/lib/python3.10/site-packages/django/db/backends/sqlite3/base.py", line 328, in execute
    return super().execute(query, params)
sqlite3.IntegrityError: NOT NULL constraint failed: store_order.payment_method

The above exception was the direct cause of the following exception:

Traceback (most recent call last):
  File "/home/ubuntu/venv/lib/python3.10/site-packages/django/core/handlers/exception.py", line 55, in inner
    response = get_response(request)
  File "/home/ubuntu/venv/lib/python3.10/site-packages/django/core/handlers/base.py", line 197, in _get_response
    response = wrapped_callback(request, *callback_args, **callback_kwargs)
  File "/home/ubuntu/venv/lib/python3.10/site-packages/django/views/decorators/csrf.py", line 56, in wrapper_view
    return view_func(*args, **kwargs)
  File "/home/ubuntu/venv/lib/python3.10/site-packages/django/views/generic/base.py", line 104, in view
    return self.dispatch(request, *args, **kwargs)
  File "/home/ubuntu/venv/lib/python3.10/site-packages/rest_framework/views.py", line 509, in dispatch
    response = self.handle_exception(exc)
  File "/home/ubuntu/venv/lib/python3.10/site-packages/rest_framework/views.py", line 469, in handle_exception
    self.raise_uncaught_exception(exc)
  File "/home/ubuntu/venv/lib/python3.10/site-packages/rest_framework/views.py", line 480, in raise_uncaught_exception
    raise exc
  File "/home/ubuntu/venv/lib/python3.10/site-packages/rest_framework/views.py", line 506, in dispatch
    response = handler(request, *args, **kwargs)
  File "/home/ubuntu/ecommerce/store/api_view.py", line 106, in post
    order = Order.objects.create(user=user, total=total, payment_method=payment_method)
  File "/home/ubuntu/venv/lib/python3.10/site-packages/django/db/models/manager.py", line 87, in manager_method
    return getattr(self.get_queryset(), name)(*args, **kwargs)
  File "/home/ubuntu/venv/lib/python3.10/site-packages/django/db/models/query.py", line 658, in create
    obj.save(force_insert=True, using=self.db)
  File "/home/ubuntu/ecommerce/store/models.py", line 101, in save
    super().save(*args, **kwargs)
  File "/home/ubuntu/venv/lib/python3.10/site-packages/django/db/models/base.py", line 814, in save
    self.save_base(
  File "/home/ubuntu/venv/lib/python3.10/site-packages/django/db/models/base.py", line 877, in save_base
    updated = self._save_table(
  File "/home/ubuntu/venv/lib/python3.10/site-packages/django/db/models/base.py", line 1020, in _save_table
    results = self._do_insert(
  File "/home/ubuntu/venv/lib/python3.10/site-packages/django/db/models/base.py", line 1061, in _do_insert
    return manager._insert(
  File "/home/ubuntu/venv/lib/python3.10/site-packages/django/db/models/manager.py", line 87, in manager_method
    return getattr(self.get_queryset(), name)(*args, **kwargs)
  File "/home/ubuntu/venv/lib/python3.10/site-packages/django/db/models/query.py", line 1805, in _insert
    return query.get_compiler(using=using).execute_sql(returning_fields)
  File "/home/ubuntu/venv/lib/python3.10/site-packages/django/db/models/sql/compiler.py", line 1822, in execute_sql
    cursor.execute(sql, params)
  File "/home/ubuntu/venv/lib/python3.10/site-packages/django/db/backends/utils.py", line 102, in execute
    return super().execute(sql, params)
  File "/home/ubuntu/venv/lib/python3.10/site-packages/django/db/backends/utils.py", line 67, in execute
    return self._execute_with_wrappers(
  File "/home/ubuntu/venv/lib/python3.10/site-packages/django/db/backends/utils.py", line 80, in _execute_with_wrappers
    return executor(sql, params, many, context)
  File "/home/ubuntu/venv/lib/python3.10/site-packages/django/db/backends/utils.py", line 84, in _execute
    with self.db.wrap_database_errors:
  File "/home/ubuntu/venv/lib/python3.10/site-packages/django/db/utils.py", line 91, in __exit__
    raise dj_exc_value.with_traceback(traceback) from exc_value
  File "/home/ubuntu/venv/lib/python3.10/site-packages/django/db/backends/utils.py", line 89, in _execute
    return self.cursor.execute(sql, params)
  File "/home/ubuntu/venv/lib/python3.10/site-packages/django/db/backends/sqlite3/base.py", line 328, in execute
    return super().execute(query, params)
django.db.utils.IntegrityError: NOT NULL constraint failed: store_order.payment_method
Internal Server Error: /order-confirm/
Traceback (most recent call last):
  File "/home/ubuntu/venv/lib/python3.10/site-packages/django/core/handlers/exception.py", line 55, in inner
    response = get_response(request)
  File "/home/ubuntu/venv/lib/python3.10/site-packages/django/core/handlers/base.py", line 197, in _get_response
    response = wrapped_callback(request, *callback_args, **callback_kwargs)
  File "/home/ubuntu/venv/lib/python3.10/site-packages/django/views/generic/base.py", line 104, in view
    return self.dispatch(request, *args, **kwargs)
  File "/home/ubuntu/venv/lib/python3.10/site-packages/django/views/generic/base.py", line 143, in dispatch
    return handler(request, *args, **kwargs)
  File "/home/ubuntu/venv/lib/python3.10/site-packages/django/views/generic/detail.py", line 109, in get
    context = self.get_context_data(object=self.object)
  File "/home/ubuntu/ecommerce/store/views.py", line 329, in get_context_data
    order_items = order.orderitem_set.all()
AttributeError: 'NoneType' object has no attribute 'orderitem_set'
[29/Feb/2024 19:15:46] "POST /api/order-confirm/ HTTP/1.1" 500 186533
[29/Feb/2024 19:15:46] "GET /order-confirm/ HTTP/1.1" 500 78335
Not Found: /favicon.ico
[29/Feb/2024 19:15:50] "GET /favicon.ico HTTP/1.1" 404 5509
Internal Server Error: /order-confirm/
Traceback (most recent call last):
  File "/home/ubuntu/venv/lib/python3.10/site-packages/django/core/handlers/exception.py", line 55, in inner
    response = get_response(request)
  File "/home/ubuntu/venv/lib/python3.10/site-packages/django/core/handlers/base.py", line 197, in _get_response
    response = wrapped_callback(request, *callback_args, **callback_kwargs)
  File "/home/ubuntu/venv/lib/python3.10/site-packages/django/views/generic/base.py", line 104, in view
    return self.dispatch(request, *args, **kwargs)
  File "/home/ubuntu/venv/lib/python3.10/site-packages/django/views/generic/base.py", line 143, in dispatch
    return handler(request, *args, **kwargs)
  File "/home/ubuntu/venv/lib/python3.10/site-packages/django/views/generic/detail.py", line 109, in get
    context = self.get_context_data(object=self.object)
  File "/home/ubuntu/ecommerce/store/views.py", line 329, in get_context_data
    order_items = order.orderitem_set.all()
AttributeError: 'NoneType' object has no attribute 'orderitem_set'
[29/Feb/2024 19:17:00] "GET /order-confirm/ HTTP/1.1" 500 78317
